Workbook

Sheet Sheet1
A1: Kontoplan
P3: den 27 december 2025
P4: Sida 1 / 2
P7: USER_B1C8654F5C2B4759BB1E86754FC7249F
A8: ODLANU i Sverige AB
A13: Nr | B13: Namn | D13: Resultaträkning/Balansräkning | F13: Kontotyp | I13: Direktbokföring | K13: Summeringsintervall | M13: Typ av bokföring | O13: Gen. rörelsebokföringsmall | R13: Produktbokföringsmall | T13: Konsoliderad omräkningsmetod
A17: 1000 | B17: BALANSRÄKNING | D17: Balansräkning | F17: Rubrik | T17: Genomsnittskurs (manuell) | X17: =VLOOKUP(A17,'Ark1'!A:A,1,FALSE) -> #N/A | Y17: =VLOOKUP(A17,'Ark1'!A:B,2,FALSE) -> #N/A
X18: =VLOOKUP(A18,'Ark1'!A:A,1,FALSE) -> #N/A | Y18: =VLOOKUP(A18,'Ark1'!A:B,2,FALSE) -> #N/A
A19: 1002 | B19: TILLGÅNGAR | D19: Balansräkning | F19: Från-Summa | T19: Genomsnittskurs (manuell) | X19: =VLOOKUP(A19,'Ark1'!A:A,1,FALSE) -> #N/A | Y19: =VLOOKUP(A19,'Ark1'!A:B,2,FALSE) -> #N/A
X20: =VLOOKUP(A20,'Ark1'!A:A,1,FALSE) -> #N/A | Y20: =VLOOKUP(A20,'Ark1'!A:B,2,FALSE) -> #N/A
A21: 1003 | B21: Anläggningstillgångar | D21: Balansräkning | F21: Från-Summa | T21: Genomsnittskurs (manuell) | X21: =VLOOKUP(A21,'Ark1'!A:A,1,FALSE) -> #N/A | Y21: =VLOOKUP(A21,'Ark1'!A:B,2,FALSE) -> #N/A
A22: 1005 | B22: Materiella anl.tillgångar | D22: Balansräkning | F22: Från-Summa | T22: Genomsnittskurs (manuell) | X22: =VLOOKUP(A22,'Ark1'!A:A,1,FALSE) -> #N/A | Y22: =VLOOKUP(A22,'Ark1'!A:B,2,FALSE) -> #N/A
A23: 1100 | B23: Byggnader och mark, Från-summa | D23: Balansräkning | F23: Från-Summa | T23: Genomsnittskurs (manuell) | X23: =VLOOKUP(A23,'Ark1'!A:A,1,FALSE) -> #N/A | Y23: =VLOOKUP(A23,'Ark1'!A:B,2,FALSE) -> #N/A
A24: 1110 | B24: Byggnader och mark | D24: Balansräkning | F24: Bokföring | I24: Ja | X24: =VLOOKUP(A24,'Ark1'!A:A,1,FALSE) -> #N/A | Y24: =VLOOKUP(A24,'Ark1'!A:B,2,FALSE) -> #N/A
A25: 1115 | B25: Ökningar under året – byggnader | D25: Balansräkning | F25: Bokföring | I25: Ja | M25: Inköp | O25: INRIKES | R25: DIV | X25: =VLOOKUP(A25,'Ark1'!A:A,1,FALSE) -> #N/A | Y25: =VLOOKUP(A25,'Ark1'!A:B,2,FALSE) -> #N/A
A26: 1116 | B26: Minskningar under året – byggnader | D26: Balansräkning | F26: Bokföring | I26: Ja | M26: Försäljning | O26: INRIKES | R26: DIV | X26: =VLOOKUP(A26,'Ark1'!A:A,1,FALSE) -> #N/A | Y26: =VLOOKUP(A26,'Ark1'!A:B,2,FALSE) -> #N/A
A27: 1190 | B27: Byggnader och mark totalt | D27: Balansräkning | F27: Till-Summa | K27: 1100..1190 | T27: Genomsnittskurs (manuell) | X27: =VLOOKUP(A27,'Ark1'!A:A,1,FALSE) -> #N/A | Y27: =VLOOKUP(A27,'Ark1'!A:B,2,FALSE) -> #N/A
A28: 1200 | B28: Maskiner och inventarier, Från-summa | D28: Balansräkning | F28: Från-Summa | T28: Genomsnittskurs (manuell) | X28: =VLOOKUP(A28,'Ark1'!A:A,1,FALSE) -> #N/A | Y28: =VLOOKUP(A28,'Ark1'!A:B,2,FALSE) -> #N/A
A29: 1210 | B29: Maskiner och inventarier | D29: Balansräkning | F29: Bokföring | I29: Ja | X29: =VLOOKUP(A29,'Ark1'!A:A,1,FALSE) -> 1210 | Y29: =VLOOKUP(A29,'Ark1'!A:B,2,FALSE) -> Anläggningar och maskiner
A30: 1215 | B30: Ökningar under året | D30: Balansräkning | F30: Bokföring | I30: Ja | X30: =VLOOKUP(A30,'Ark1'!A:A,1,FALSE) -> #N/A | Y30: =VLOOKUP(A30,'Ark1'!A:B,2,FALSE) -> #N/A
A31: 1216 | B31: Minskningar under året | D31: Balansräkning | F31: Bokföring | I31: Ja | M31: Försäljning | O31: INRIKES | R31: DIV | X31: =VLOOKUP(A31,'Ark1'!A:A,1,FALSE) -> #N/A | Y31: =VLOOKUP(A31,'Ark1'!A:B,2,FALSE) -> #N/A
A32: 1219 | B32: Ackumulerade avskrivningar | D32: Balansräkning | F32: Bokföring | I32: Ja | X32: =VLOOKUP(A32,'Ark1'!A:A,1,FALSE) -> 1219 | Y32: =VLOOKUP(A32,'Ark1'!A:B,2,FALSE) -> Ack avskrivningar verktyg och maskiner
A33: 1220 | B33: Maskiner och inventarier total | D33: Balansräkning | F33: Till-Summa | K33: 1200..1220 | T33: Genomsnittskurs (manuell) | X33: =VLOOKUP(A33,'Ark1'!A:A,1,FALSE) -> 1220 | Y33: =VLOOKUP(A33,'Ark1'!A:B,2,FALSE) -> Verktyg och installationer
A34: 1240 | B34: Fordon, Från-Summa | D34: Balansräkning | F34: Från-Summa | T34: Genomsnittskurs (manuell) | X34: =VLOOKUP(A34,'Ark1'!A:A,1,FALSE) -> 1240 | Y34: =VLOOKUP(A34,'Ark1'!A:B,2,FALSE) -> Fordon för transport
A35: 1241 | B35: Fordon | D35: Balansräkning | F35: Bokföring | I35: Ja | X35: =VLOOKUP(A35,'Ark1'!A:A,1,FALSE) -> #N/A | Y35: =VLOOKUP(A35,'Ark1'!A:B,2,FALSE) -> #N/A
A36: 1245 | B36: Ökningar under året | D36: Balansräkning | F36: Bokföring | I36: Ja | M36: Inköp | O36: INRIKES | R36: DIV | X36: =VLOOKUP(A36,'Ark1'!A:A,1,FALSE) -> #N/A | Y36: =VLOOKUP(A36,'Ark1'!A:B,2,FALSE) -> #N/A
A37: 1246 | B37: Minskningar under året – fordon | D37: Balansräkning | F37: Bokföring | I37: Ja | M37: Försäljning | O37: INRIKES | R37: DIV | X37: =VLOOKUP(A37,'Ark1'!A:A,1,FALSE) -> #N/A | Y37: =VLOOKUP(A37,'Ark1'!A:B,2,FALSE) -> #N/A
A38: 1249 | B38: Ack. avskrivning på bilar | D38: Balansräkning | F38: Bokföring | I38: Ja | X38: =VLOOKUP(A38,'Ark1'!A:A,1,FALSE) -> 1249 | Y38: =VLOOKUP(A38,'Ark1'!A:B,2,FALSE) -> Ack avskrivningar fordon för transport
A39: 1250 | B39: Bilar och transp.medel totalt | D39: Balansräkning | F39: Till-Summa | K39: 1240..1250 | T39: Genomsnittskurs (manuell) | X39: =VLOOKUP(A39,'Ark1'!A:A,1,FALSE) -> #N/A | Y39: =VLOOKUP(A39,'Ark1'!A:B,2,FALSE) -> #N/A
A40: 1260 | B40: Materiella anl.tillg. totalt | D40: Balansräkning | F40: Till-Summa | K40: 1005..1260 | T40: Genomsnittskurs (manuell) | X40: =VLOOKUP(A40,'Ark1'!A:A,1,FALSE) -> #N/A | Y40: =VLOOKUP(A40,'Ark1'!A:B,2,FALSE) -> #N/A
A41: 1300 | B41: Värdepapper | D41: Balansräkning | F41: Från-Summa | T41: Genomsnittskurs (manuell) | X41: =VLOOKUP(A41,'Ark1'!A:A,1,FALSE) -> #N/A | Y41: =VLOOKUP(A41,'Ark1'!A:B,2,FALSE) -> #N/A
A42: 1310 | B42: Aktier och andelar koncernftg | D42: Balansräkning | F42: Bokföring | I42: Ja | X42: =VLOOKUP(A42,'Ark1'!A:A,1,FALSE) -> #N/A | Y42: =VLOOKUP(A42,'Ark1'!A:B,2,FALSE) -> #N/A
A43: 1397 | B43: Finansiella anlägg.tillg. tot. | D43: Balansräkning | F43: Till-Summa | K43: 1300..1397 | T43: Genomsnittskurs (manuell) | X43: =VLOOKUP(A43,'Ark1'!A:A,1,FALSE) -> #N/A | Y43: =VLOOKUP(A43,'Ark1'!A:B,2,FALSE) -> #N/A
A44: 1398 | B44: Anläggningstillgångar totalt | D44: Balansräkning | F44: Till-Summa | K44: 1003..1398 | T44: Genomsnittskurs (manuell) | X44: =VLOOKUP(A44,'Ark1'!A:A,1,FALSE) -> #N/A | Y44: =VLOOKUP(A44,'Ark1'!A:B,2,FALSE) -> #N/A
X45: =VLOOKUP(A45,'Ark1'!A:A,1,FALSE) -> #N/A | Y45: =VLOOKUP(A45,'Ark1'!A:B,2,FALSE) -> #N/A
A46: 1400 | B46: Omsättningstillgångar | D46: Balansräkning | F46: Från-Summa | T46: Genomsnittskurs (manuell) | X46: =VLOOKUP(A46,'Ark1'!A:A,1,FALSE) -> #N/A | Y46: =VLOOKUP(A46,'Ark1'!A:B,2,FALSE) -> #N/A
A47: 1401 | B47: Lager | D47: Balansräkning | F47: Från-Summa | T47: Genomsnittskurs (manuell) | X47: =VLOOKUP(A47,'Ark1'!A:A,1,FALSE) -> #N/A | Y47: =VLOOKUP(A47,'Ark1'!A:B,2,FALSE) -> #N/A
A48: 1410 | B48: Råmaterial | D48: Balansräkning | F48: Bokföring | I48: Ja | X48: =VLOOKUP(A48,'Ark1'!A:A,1,FALSE) -> 1410 | Y48: =VLOOKUP(A48,'Ark1'!A:B,2,FALSE) -> Råvarulager
A49: 1411 | B49: Råmaterial (interim) | D49: Balansräkning | F49: Bokföring | I49: Ja | X49: =VLOOKUP(A49,'Ark1'!A:A,1,FALSE) -> #N/A | Y49: =VLOOKUP(A49,'Ark1'!A:B,2,FALSE) -> #N/A
A50: 1430 | B50: PIA för projekt | D50: Balansräkning | F50: Från-Summa | T50: Genomsnittskurs (manuell) | X50: =VLOOKUP(A50,'Ark1'!A:A,1,FALSE) -> #N/A | Y50: =VLOOKUP(A50,'Ark1'!A:B,2,FALSE) -> #N/A
...

Sheet Sheet2
A1: Kontoplan
P3: den 27 december 2025
P4: Sida 2 / 2
P7: USER_B1C8654F5C2B4759BB1E86754FC7249F
A8: ODLANU i Sverige AB
A13: Nr | B13: Namn | D13: Resultaträkning/Balansräkning | F13: Kontotyp | I13: Direktbokföring | K13: Summeringsintervall | M13: Typ av bokföring | O13: Gen. rörelsebokföringsmall | R13: Produktbokföringsmall | T13: Konsoliderad omräkningsmetod
A17: 3000 | B17: RESULTATRÄKNING | D17: Resultaträkning | F17: Rubrik | T17: Genomsnittskurs (manuell) | X17: =VLOOKUP(A17,'Ark1'!A:C,1,FALSE) -> #N/A | Y17: =VLOOKUP(A17,'Ark1'!A:B,2,FALSE) -> #N/A
X18: =VLOOKUP(A18,'Ark1'!A:C,1,FALSE) -> #N/A | Y18: =VLOOKUP(A18,'Ark1'!A:B,2,FALSE) -> #N/A
A19: 3002 | B19: Intäkt | D19: Resultaträkning | F19: Från-Summa | T19: Genomsnittskurs (manuell) | X19: =VLOOKUP(A19,'Ark1'!A:C,1,FALSE) -> #N/A | Y19: =VLOOKUP(A19,'Ark1'!A:B,2,FALSE) -> #N/A
A20: 3050 | B20: Försäljning varor | D20: Resultaträkning | F20: Från-Summa | T20: Genomsnittskurs (manuell) | X20: =VLOOKUP(A20,'Ark1'!A:C,1,FALSE) -> #N/A | Y20: =VLOOKUP(A20,'Ark1'!A:B,2,FALSE) -> #N/A
A21: 3051 | B21: Försäljning varor inom Sverige | D21: Resultaträkning | F21: Bokföring | I21: Ja | M21: Försäljning | O21: INRIKES | R21: DETALJ | X21: =VLOOKUP(A21,'Ark1'!A:C,1,FALSE) -> 3051 | Y21: =VLOOKUP(A21,'Ark1'!A:B,2,FALSE) -> Försäljning E handel
A22: 3055 | B22: Försäljning varor utom EU | D22: Resultaträkning | F22: Bokföring | I22: Ja | M22: Försäljning | O22: EXPORT | R22: DETALJ | X22: =VLOOKUP(A22,'Ark1'!A:C,1,FALSE) -> #N/A | Y22: =VLOOKUP(A22,'Ark1'!A:B,2,FALSE) -> #N/A
A23: 3056 | B23: Försäljning varor inom EU | D23: Resultaträkning | F23: Bokföring | I23: Ja | M23: Försäljning | O23: EU | R23: DETALJ | X23: =VLOOKUP(A23,'Ark1'!A:C,1,FALSE) -> #N/A | Y23: =VLOOKUP(A23,'Ark1'!A:B,2,FALSE) -> #N/A
A24: 3057 | B24: Projektförs. kopplade varor | D24: Resultaträkning | F24: Bokföring | I24: Ja | X24: =VLOOKUP(A24,'Ark1'!A:C,1,FALSE) -> #N/A | Y24: =VLOOKUP(A24,'Ark1'!A:B,2,FALSE) -> #N/A
A25: 3059 | B25: Försäljning varor totalt | D25: Resultaträkning | F25: Till-Summa | K25: 3050..3059 | T25: Genomsnittskurs (manuell) | X25: =VLOOKUP(A25,'Ark1'!A:C,1,FALSE) -> #N/A | Y25: =VLOOKUP(A25,'Ark1'!A:B,2,FALSE) -> #N/A
A26: 3060 | B26: Försäljning av råmaterial | D26: Resultaträkning | F26: Från-Summa | T26: Genomsnittskurs (manuell) | X26: =VLOOKUP(A26,'Ark1'!A:C,1,FALSE) -> #N/A | Y26: =VLOOKUP(A26,'Ark1'!A:B,2,FALSE) -> #N/A
A27: 3061 | B27: Försäljning råmaterial inom SE | D27: Resultaträkning | F27: Bokföring | I27: Ja | M27: Försäljning | O27: INRIKES | R27: RÅMAT | X27: =VLOOKUP(A27,'Ark1'!A:C,1,FALSE) -> #N/A | Y27: =VLOOKUP(A27,'Ark1'!A:B,2,FALSE) -> #N/A
A28: 3065 | B28: Försäljning råmaterial utom EU | D28: Resultaträkning | F28: Bokföring | I28: Ja | M28: Försäljning | O28: EXPORT | R28: RÅMAT | X28: =VLOOKUP(A28,'Ark1'!A:C,1,FALSE) -> #N/A | Y28: =VLOOKUP(A28,'Ark1'!A:B,2,FALSE) -> #N/A
A29: 3066 | B29: Försäljning råmaterial inom EU | D29: Resultaträkning | F29: Bokföring | I29: Ja | M29: Försäljning | O29: EU | R29: RÅMAT | X29: =VLOOKUP(A29,'Ark1'!A:C,1,FALSE) -> #N/A | Y29: =VLOOKUP(A29,'Ark1'!A:B,2,FALSE) -> #N/A
A30: 3067 | B30: Projektförs. kopplat råmat. | D30: Resultaträkning | F30: Bokföring | I30: Ja | X30: =VLOOKUP(A30,'Ark1'!A:C,1,FALSE) -> #N/A | Y30: =VLOOKUP(A30,'Ark1'!A:B,2,FALSE) -> #N/A
A31: 3069 | B31: Försäljning råmaterial totalt | D31: Resultaträkning | F31: Till-Summa | K31: 3060..3069 | T31: Genomsnittskurs (manuell) | X31: =VLOOKUP(A31,'Ark1'!A:C,1,FALSE) -> #N/A | Y31: =VLOOKUP(A31,'Ark1'!A:B,2,FALSE) -> #N/A
A32: 3070 | B32: Försäljning resurser | D32: Resultaträkning | F32: Från-Summa | T32: Genomsnittskurs (manuell) | X32: =VLOOKUP(A32,'Ark1'!A:C,1,FALSE) -> #N/A | Y32: =VLOOKUP(A32,'Ark1'!A:B,2,FALSE) -> #N/A
A33: 3071 | B33: Försäljning resurser inom SE | D33: Resultaträkning | F33: Bokföring | I33: Ja | M33: Försäljning | O33: INRIKES | R33: TJÄNSTER | X33: =VLOOKUP(A33,'Ark1'!A:C,1,FALSE) -> #N/A | Y33: =VLOOKUP(A33,'Ark1'!A:B,2,FALSE) -> #N/A
A34: 3075 | B34: Försäljning resurser utom EU | D34: Resultaträkning | F34: Bokföring | I34: Ja | M34: Försäljning | O34: EXPORT | R34: TJÄNSTER | X34: =VLOOKUP(A34,'Ark1'!A:C,1,FALSE) -> 3075 | Y34: =VLOOKUP(A34,'Ark1'!A:B,2,FALSE) -> Detaljhandel e-handel frakt
A35: 3076 | B35: Försäljning resurser inom EU | D35: Resultaträkning | F35: Bokföring | I35: Ja | M35: Försäljning | O35: EU | R35: TJÄNSTER | X35: =VLOOKUP(A35,'Ark1'!A:C,1,FALSE) -> #N/A | Y35: =VLOOKUP(A35,'Ark1'!A:B,2,FALSE) -> #N/A
A36: 3077 | B36: Projektförs. kopplade resurser | D36: Resultaträkning | F36: Bokföring | I36: Ja | X36: =VLOOKUP(A36,'Ark1'!A:C,1,FALSE) -> #N/A | Y36: =VLOOKUP(A36,'Ark1'!A:B,2,FALSE) -> #N/A
A37: 3079 | B37: Försäljning resurser totalt | D37: Resultaträkning | F37: Till-Summa | K37: 3070..3079 | T37: Genomsnittskurs (manuell) | X37: =VLOOKUP(A37,'Ark1'!A:C,1,FALSE) -> #N/A | Y37: =VLOOKUP(A37,'Ark1'!A:B,2,FALSE) -> #N/A
A38: 3080 | B38: Försäljning projekt | D38: Resultaträkning | F38: Från-Summa | T38: Genomsnittskurs (manuell) | X38: =VLOOKUP(A38,'Ark1'!A:C,1,FALSE) -> #N/A | Y38: =VLOOKUP(A38,'Ark1'!A:B,2,FALSE) -> #N/A
A39: 3081 | B39: Försäljning projekt övrigt | D39: Resultaträkning | F39: Bokföring | I39: Ja | M39: Försäljning | O39: INRIKES | R39: DIV | X39: =VLOOKUP(A39,'Ark1'!A:C,1,FALSE) -> #N/A | Y39: =VLOOKUP(A39,'Ark1'!A:B,2,FALSE) -> #N/A
A40: 3085 | B40: Projektförsäljning | D40: Resultaträkning | F40: Bokföring | I40: Ja | X40: =VLOOKUP(A40,'Ark1'!A:C,1,FALSE) -> #N/A | Y40: =VLOOKUP(A40,'Ark1'!A:B,2,FALSE) -> #N/A
A41: 3089 | B41: Försäljning projekt totalt | D41: Resultaträkning | F41: Till-Summa | K41: 3080..3089 | T41: Genomsnittskurs (manuell) | X41: =VLOOKUP(A41,'Ark1'!A:C,1,FALSE) -> #N/A | Y41: =VLOOKUP(A41,'Ark1'!A:B,2,FALSE) -> #N/A
A42: 3090 | B42: Konsultation inom Sverige | D42: Resultaträkning | F42: Bokföring | I42: Ja | M42: Försäljning | O42: INRIKES | R42: TJÄNSTER | X42: =VLOOKUP(A42,'Ark1'!A:C,1,FALSE) -> #N/A | Y42: =VLOOKUP(A42,'Ark1'!A:B,2,FALSE) -> #N/A
A43: 3091 | B43: Försäljning servicekontrakt | D43: Resultaträkning | F43: Bokföring | I43: Ja | O43: INRIKES | R43: TJÄNSTER | X43: =VLOOKUP(A43,'Ark1'!A:C,1,FALSE) -> #N/A | Y43: =VLOOKUP(A43,'Ark1'!A:B,2,FALSE) -> #N/A
A44: 3095 | B44: Övriga fakturerade kostnader | D44: Resultaträkning | F44: Bokföring | I44: Ja | M44: Försäljning | O44: INRIKES | R44: DIV | X44: =VLOOKUP(A44,'Ark1'!A:C,1,FALSE) -> #N/A | Y44: =VLOOKUP(A44,'Ark1'!A:B,2,FALSE) -> #N/A
A45: 3098 | B45: Intäktsreduktioner | D45: Resultaträkning | F45: Bokföring | I45: Ja | X45: =VLOOKUP(A45,'Ark1'!A:C,1,FALSE) -> #N/A | Y45: =VLOOKUP(A45,'Ark1'!A:B,2,FALSE) -> #N/A
A46: 3731 | B46: Lämnade kassarabatter | D46: Resultaträkning | F46: Bokföring | I46: Ja | X46: =VLOOKUP(A46,'Ark1'!A:C,1,FALSE) -> #N/A | Y46: =VLOOKUP(A46,'Ark1'!A:B,2,FALSE) -> #N/A
A47: 3732 | B47: Lämnade kassarabatter 2 | D47: Resultaträkning | F47: Bokföring | I47: Ja | X47: =VLOOKUP(A47,'Ark1'!A:C,1,FALSE) -> #N/A | Y47: =VLOOKUP(A47,'Ark1'!A:B,2,FALSE) -> #N/A
A48: 3740 | B48: Fakturaavrundning | D48: Resultaträkning | F48: Bokföring | I48: Ja | O48: INRIKES | R48: NO VAT | X48: =VLOOKUP(A48,'Ark1'!A:C,1,FALSE) -> 3740 | Y48: =VLOOKUP(A48,'Ark1'!A:B,2,FALSE) -> Öresavrundning
A49: 3999 | B49: Totala intäkter | D49: Resultaträkning | F49: Till-Summa | K49: 3002..3999 | T49: Genomsnittskurs (manuell) | X49: =VLOOKUP(A49,'Ark1'!A:C,1,FALSE) -> #N/A | Y49: =VLOOKUP(A49,'Ark1'!A:B,2,FALSE) -> #N/A
X50: =VLOOKUP(A50,'Ark1'!A:C,1,FALSE) -> #N/A | Y50: =VLOOKUP(A50,'Ark1'!A:B,2,FALSE) -> #N/A
...

Sheet Ark1
A1: RÖRELSENS INTÄKTER Nettoomsättning
A2: 3051 | B2: Försäljning E handel | C2: 862 696,48 | D2: =VLOOKUP(A2,Sheet2!A:G,1,FALSE) -> 3051
A3: 3052 | B3: Reklamationer | C3: 129 507,20 | D3: =VLOOKUP(A3,Sheet2!A:G,1,FALSE) -> #N/A
A4: 3072 | B4: Detaljhandel e-handel övrig fysisk | C4: 0 | D4: =VLOOKUP(A4,Sheet2!A:G,1,FALSE) -> #N/A
A5: 3075 | B5: Detaljhandel e-handel frakt | C5: 0 | D5: =VLOOKUP(A5,Sheet2!A:G,1,FALSE) -> 3075
A6: 3078 | B6: Detaljhandel B2B övrig | C6: 0 | D6: =VLOOKUP(A6,Sheet2!A:G,1,FALSE) -> #N/A
A7: 3520 | B7: Färsäljning frakt | C7: 0 | D7: =VLOOKUP(A7,Sheet2!A:G,1,FALSE) -> #N/A
A8: 3740 | B8: Öresavrundning | C8: 78.57 | D8: =VLOOKUP(A8,Sheet2!A:G,1,FALSE) -> 3740
A9: Summa nettoomsättning | C9: 992 282,25 | D9: =VLOOKUP(A9,Sheet2!A:G,1,FALSE) -> #N/A
A10: Övriga rörelseintäkter | D10: =VLOOKUP(A10,Sheet2!A:G,1,FALSE) -> #N/A
A11: 3902 | B11: Momsfria intäkter | C11: 0 | D11: =VLOOKUP(A11,Sheet2!A:G,1,FALSE) -> #N/A
A12: 3950 | B12: Återvunna kundförluster | C12: 1 301,98 | D12: =VLOOKUP(A12,Sheet2!A:G,1,FALSE) -> #N/A
A13: 3961 | B13: Valutakursvinster rörelseskulder | C13: 0 | D13: =VLOOKUP(A13,Sheet2!A:G,1,FALSE) -> #N/A
A14: Summa övriga rörelseintäkter | C14: 1 301,98 | D14: =VLOOKUP(A14,Sheet2!A:G,1,FALSE) -> #N/A
A15: SUMMA RÖRELSENS INTÄKTER | C15: 993 584,23 | D15: =VLOOKUP(A15,Sheet2!A:G,1,FALSE) -> #N/A
A16: RÖRELSENS KOSTNADER | D16: =VLOOKUP(A16,Sheet2!A:G,1,FALSE) -> #N/A
A17: Råvaror och förnödenheter | D17: =VLOOKUP(A17,Sheet2!A:G,1,FALSE) -> #N/A
A18: 4000 | B18: Inköp varor | C18: 0 | D18: =VLOOKUP(A18,Sheet2!A:G,1,FALSE) -> 4000
A19: 4010 | B19: Kostnad sålda varor | C19: -409 203,00 | D19: =VLOOKUP(A19,Sheet2!A:G,1,FALSE) -> #N/A
A20: 4043 | B20: Kostnad sålda varor droppshipping | C20: -23 231,43 | D20: =VLOOKUP(A20,Sheet2!A:G,1,FALSE) -> #N/A
A21: 4050 | B21: Fraktkostnader inkommade varor | C21: -7 399,70 | D21: =VLOOKUP(A21,Sheet2!A:G,1,FALSE) -> #N/A
A22: 4056 | B22: Inköp tjänster EU | C22: -32 393,84 | D22: =VLOOKUP(A22,Sheet2!A:G,1,FALSE) -> 4056
A23: 4402 | B23: Kostnader produktionskostnader varuhus, emballage | C23: -37 385,80 | D23: =VLOOKUP(A23,Sheet2!A:G,1,FALSE) -> #N/A
A24: 4543 | B24: Inköp EU | C24: 267 703,99 | D24: =VLOOKUP(A24,Sheet2!A:G,1,FALSE) -> #N/A
A25: 4549 | B25: Motkontering inköp EU | C25: -261 904,15 | D25: =VLOOKUP(A25,Sheet2!A:G,1,FALSE) -> #N/A
A26: Summa råvaror och förnödenheter | C26: -503 813,93 | D26: =VLOOKUP(A26,Sheet2!A:G,1,FALSE) -> #N/A
A27: BRUTTOVINST | C27: 489 770,30 | D27: =VLOOKUP(A27,Sheet2!A:G,1,FALSE) -> #N/A
A28: Övriga externa kostnader | D28: =VLOOKUP(A28,Sheet2!A:G,1,FALSE) -> #N/A
A29: 5011 | B29: Hyreskostnader | C29: 0 | D29: =VLOOKUP(A29,Sheet2!A:G,1,FALSE) -> #N/A
A30: 5020 | B30: Hyreskostnader - el | C30: -106 920,80 | D30: =VLOOKUP(A30,Sheet2!A:G,1,FALSE) -> #N/A
A31: 5061 | B31: Hyreskostander - städ | C31: -3 760,00 | D31: =VLOOKUP(A31,Sheet2!A:G,1,FALSE) -> #N/A
A32: 5062 | B32: Hyreskostnader - sophämtning | C32: -1 148,80 | D32: =VLOOKUP(A32,Sheet2!A:G,1,FALSE) -> #N/A
A33: 5090 | B33: Hyreskostnader - övrigt | C33: -21 245,46 | D33: =VLOOKUP(A33,Sheet2!A:G,1,FALSE) -> #N/A
A34: 5422 | B34: Licenser programvara - backoffice (server) | C34: 0 | D34: =VLOOKUP(A34,Sheet2!A:G,1,FALSE) -> #N/A
A35: 5423 | B35: Licenser programvara - digital verksamhet | C35: -61 241,52 | D35: =VLOOKUP(A35,Sheet2!A:G,1,FALSE) -> #N/A
A36: 5460 | B36: Förbrukningsmaterial | C36: -12 298,68 | D36: =VLOOKUP(A36,Sheet2!A:G,1,FALSE) -> #N/A
A37: 5480 | B37: Arbetskläder & Reklam material | C37: 0 | D37: =VLOOKUP(A37,Sheet2!A:G,1,FALSE) -> #N/A
A38: 5611 | B38: Personbilar drivmedel | C38: -913.27 | D38: =VLOOKUP(A38,Sheet2!A:G,1,FALSE) -> 5611
A39: 5612 | B39: Personbilar försäkring & skatt | C39: -2 587,00 | D39: =VLOOKUP(A39,Sheet2!A:G,1,FALSE) -> 5612
A40: 5619 | B40: Personbilar övrigt | C40: 0 | D40: =VLOOKUP(A40,Sheet2!A:G,1,FALSE) -> #N/A
...
